Workbook

Sheet Copan_Reservas
C1: 2025 | N1: 2026
B2: Quantidade dias no mês | C2: 31 | D2: 30 | E2: 30 | F2: 30 | G2: 31 | H2: 31 | I2: 30 | J2: 31 | K2: 30 | L2: 31 | M2: =SUM(C2:L2) -> 305 | N2: 31 | O2: 28 | P2: 31 | Q2: 30 | R2: 31 | S2: 30 | T2: 31 | U2: 31
C3: mar | D3: abr | E3: mai | F3: jun | G3: jul | H3: ago | I3: set | J3: out | K3: nov | L3: dez | M3: Total ano mar-dez | N3: jan | O3: fev | P3: mar | Q3: abr | R3: mai | S3: junho | T3: 2027 | U3: agosto
B4: Ocupação | C4: =C5/C2 -> 0.64516129 | D4: =D5/D2 -> 0.46666667 | E4: =E5/E2 -> 0.93333333 | F4: =F5/F2 -> 0.73333333 | G4: =G5/G2 -> 0.74193548 | H4: =H5/H2 -> 0.96774194 | I4: =I5/I2 -> 0.9 | J4: =J5/J2 -> 0.74193548 | ... U4: =U5/U2 -> 0.93548387
B5: Diárias | C5: 20 | D5: 14 | E5: 28 | F5: 22 | G5: 23 | H5: =2+28 -> 30 | I5: 27 | J5: 23 | K5: 28 | L5: 24 | M5: =SUM(C5:L5) -> 239 | N5: 20 | O5: 16 | P5: 24 | Q5: 24 | R5: 26 | S5: 30 | T5: 23 | U5: 29
B6: Quantidade Check-ins | C6: 8 | D6: 5 | E6: 11 | F6: 11 | G6: 6 | H6: 10 | I6: 6 | J6: 7 | K6: 8 | L6: 6 | M6: =SUM(C6:L6) -> 78 | N6: 7 | O6: 7 | P6: 8 | Q6: 10 | R6: 10 | S6: =1200/150 -> 8 | T6: =1200/150 -> 8 | U6: 7
B7: Média diária hóspede | C7: =SUM(C10:C13)/C5 -> 273.926 | D7: =SUM(D10:D13)/D5 -> 329.92786 | E7: =SUM(E10:E13)/E5 -> 217.89179 | F7: =SUM(F10:F13)/F5 -> 272.35682 | G7: =SUM(G10:G13)/G5 -> 252.34217 | H7: =SUM(H10:H13)/H5 -> 260.641 | I7: =SUM(I10:I13)/I5 -> 263.34296 | J7: =SUM(J10:J13)/J5 -> 290.5587 | ... U7: =SUM(U10:U13)/U5 -> 249.80793
B8: Média diária líquido | C8: =(C10+C11+C13+C14+C16)/C5 -> 196.482 | D8: =(D10+D11+D13+D14+D16)/D5 -> 254.15643 | E8: =(E10+E11+E13+E14+E16)/E5 -> 177.30036 | F8: =(F10+F11+F13+F14+F16)/F5 -> 192.39318 | G8: =(G10+G11+G13+G14+G16)/G5 -> 213.21174 | H8: =(H10+H11+H13+H14+H16)/H5 -> 207.911 | I8: =(I10+I11+I13+I14+I16)/I5 -> 230.00963 | J8: =(J10+J11+J13+J14+J16)/J5 -> 244.90652 | ... U8: =(U10+U11+U13+U14+U16)/U5 -> 213.60103
B9: Devolução a cliente | C9: 0 | D9: 0 | E9: 0 | F9: 0 | G9: 0 | H9: 0 | I9: 0 | J9: 0 | K9: 0 | L9: 0 | N9: 0 | O9: 0 | R9: 0
B10: Receita Booking | C10: 2492 | D10: 2220 | E10: 850 | F10: 840 | G10: 0 | H10: 630 | I10: 0 | J10: 0 | K10: 0 | L10: 0 | N10: 0 | O10: 0
B11: Receita Airbnb | C11: =1783.15+319.8+703.57 -> 2806.52 | D11: 1238.99 | E11: 5064.91 | F11: 5151.85 | G11: 5803.87 | H11: 7189.23 | I11: 7110.26 | J11: 6682.85 | K11: 7156.79 | L11: 7184.32 | M11: =SUM(C11:L11) -> 55389.59 | N11: 5081.59 | O11: 4342.83 | P11: =SUM(Airbnb_csv!L110:L117) -> 6965.7 | Q11: =SUM(Airbnb_csv!L121:L130) -> 6240.4 | R11: =SUM(Airbnb_csv!L133:L142) -> 7316.02 | S11: 7116 | T11: =SUM(Airbnb_csv!L157:L164) -> 6109.36 | U11: 7244.43
B12: Ajuste erro report | E12: =-(-4440.97+E11) -> -623.94 | J12: 0
B13: Receita offsite | C13: 180 | D13: =370+140+650 -> 1160 | E13: =405+405 -> 810 | F13: 0 | J13: 0 | R13: 0
B14: Lavanderia/Diarista | C14: -1200 | D14: =-150*D6 -> -750 | E14: =-150*E6 -> -1650 | F14: =-150*F6 -> -1650 | G14: =-150*G6 -> -900 | H14: =-150*H6 -> -1500 | I14: =-150*I6 -> -900 | J14: =-150*J6 -> -1050 | K14: =-150*K6 -> -1200 | L14: =-150*L6 -> -900 | M14: =SUM(C14:L14) -> -11700 | N14: =-150*N6 -> -1050 | O14: =-150*O6 -> -1050 | P14: =-150*P6 -> -1200 | Q14: =-150*Q6 -> -1500 | R14: =-SUM(Airbnb_csv!P133:P142) -> -1500 | S14: -1350 | T14: -1200 | U14: =-7*150 -> -1050
B15: Diárias Pet | D15: 0 | F15: 0 | J15: 0 | R15: 0
B16: Comissão Booking | C16: =-14%*C10 -> -348.88 | D16: -310.8 | E16: -110.5 | F16: -109.2 | G16: 0 | H16: -81.9 | I16: 0 | J16: 0
B17: Administração | C17: =-0.1*SUM(C10:C13) -> -547.852 | D17: =-0.1*SUM(D10:D13) -> -461.899 | E17: =-0.1*SUM(E10:E13) -> -610.097 | F17: =-0.1*SUM(F10:F13) -> -599.185 | G17: =-0.1*SUM(G10:G13,E12) -> -517.993 | H17: =-0.1*SUM(H10:H13,F12) -> -781.923 | I17: =-0.1*SUM(I10:I13) -> -711.026 | J17: =-0.1*SUM(J10:J13) -> -668.285 | K17: =-0.1*SUM(K10:K13) -> -715.679 | L17: =-0.1*SUM(L10:L13) -> -718.432 | M17: =SUM(C17:L17) -> -6332.371 | N17: =-0.1*SUM(N10:N13) -> -508.159 | O17: =-0.1*SUM(O10:O13) -> -434.283 | P17: =-0.1*SUM(P10:P13) -> -696.57 | Q17: =-0.1*SUM(Q10:Q13) -> -624.04 | R17: =-0.1*SUM(R10:R13) -> -731.602 | S17: =-0.1*SUM(S10:S13) -> -711.6 | T17: =-0.1*SUM(T10:T13) -> -610.936 | U17: =-0.1*SUM(U10:U13) -> -724.443
B18: Recepção | D18: 0
B19: Manutenção | D19: 0
B20: Receita líquida locação | C20: =SUM(C9:C19) -> 3381.788 | D20: =SUM(D9:D19) -> 3096.291 | E20: =SUM(E9:E19) -> 3730.373 | F20: =SUM(F9:F19) -> 3633.465 | G20: =SUM(G9:G19) -> 4385.877 | H20: =SUM(H9:H19) -> 5455.407 | I20: =SUM(I9:I19) -> 5499.234 | J20: =SUM(J9:J19) -> 4964.565 | ... L20: =SUM(L9:L19) -> 5565.888 | M20: =SUM(C20:L20) -> 44953.999 | N20: =SUM(N9:N19) -> 3523.431 | O20: =SUM(O9:O19) -> 2858.547 | P20: =SUM(P9:P19) -> 5069.13 | Q20: =SUM(Q9:Q19) -> 4116.36 | R20: =SUM(R9:R19) -> 5084.418 | S20: =SUM(S9:S19) -> 5054.4 | T20: =SUM(T9:T19) -> 4298.424 | U20: =SUM(U9:U19) -> 5469.987
R21: =R20/E20-1 -> 0.36297845 | S21: =S20/F20-1 -> 0.39106886 | T21: =T20/G20-1 -> -0.019939684 | U21: =U20/H20-1 -> 0.0026725779
B23: Offsite
C24: Checkout | D24: Receita Bruta | E24: Lavanderia | S24: =S17/2 -> -355.8 | U24: =U17/2 -> -362.2215
B25: 45769 | C25: 45769 | D25: 370 | E25: 0
B26: 45765 | C26: 45765 | D26: 140 | E26: 0
B27: 45772 | C27: 45774 | D27: 650 | E27: -150
B28: 45799 | C28: 45802 | D28: 810 | E28: -150

Sheet Planilha1
A1: Controle COPAN | G1: Controle Aportes
A2: Tipo | B2: Valor | C2: Valor por Cota | D2: Data | H2: 16250 | I2: 24.05.24
A3: Despesas Aquisição | H3: 187.5 | I3: 24.05.24
A4: Sinal CCV | B4: 65000 | C4: =B4/4 -> 16250 | D4: 24.05.24 | H4: 3683.23 | I4: 11.07.24
A5: Taxa Avaliação Caixa | B5: 750 | C5: =B5/4 -> 187.5 | D5: 04.06.24 | H5: 5191.81 | I5: 13.08.24
A6: Matrícula Atualizada | B6: 70.44 | C6: =B6/4 -> 17.61 | D6: 08.07.24
A7: Taxa Seguridade Caixa | B7: 2089.33 | C7: =B7/4 -> 522.3325 | D7: 08.07.24 | G7: Total | H7: =SUM(H2:H6) -> 25312.54
A8: ITBI | B8: 10073.16 | C8: =B8/4 -> 2518.29 | D8: 12.07.24 | G8: Total Despesas | H8: =C56 -> 35364.375
A9: Registro | B9: 5801.15 | C9: =B9/4 -> 1450.2875 | D9: 07.08.24 | G9: Saldo | H9: =H7-H8 -> -10051.835
A10: Taxa Procuração | B10: 86.08 | C10: =B10/4 -> 21.52 | D10: 07.08.24
A11: Comissão Corretor | B11: 16600 | C11: =B11/4 -> 4150 | D11: 14.08.24
A12: Despesas Approved - Despachante - Registro | B12: 780 | C12: =B12/4 -> 195 | D12: 14.08.24
A13: Total | B13: =SUM(B4:B12) -> 101250.16 | C13: =B13/4 -> 25312.54
A14: Despesas Ordinárias Mensal
A15: 45505
A16: Parcela 01/420 Financiamento | B16: 3755.59 | C16: =B16/4 -> 938.8975 | D16: 15.08.24 | G16: Início da obra | H16: 28.09.24
A17: Custo Mensal | B17: =SUM(B16) -> 3755.59 | C17: =B17/4 -> 938.8975 | G17: Previsão de término: | H17: 01.12.24
A18: 45536
A19: Condomínio Setembro | B19: 495.47 | C19: =B19/4 -> 123.8675 | D19: 06.09.24
A20: Luz | B20: 0 | C20: =B20/4 -> 0
A21: Parcela 01/420 Financiamento | B21: 3798.67 | C21: =B21/4 -> 949.6675 | D21: 01.09.24
A22: 45566
A24: Despesas - Orçamento de Obra
A25: Empreiteiro | B25: 14000 | C25: =B25/4 -> 3500
A26: Sinal | B26: 2000 | C26: =B26/4 -> 500 | D26: 28.08.2024
A27: Primeira Parcela | B27: 2000 | C27: =B27/4 -> 500 | D27: 15.09.2024
A28: Segunda Parcela | B28: 2500 | C28: =B28/4 -> 625 | D28: 30.09.2024
A29: Terceira Parcela | B29: 2500 | C29: =B29/4 -> 625 | D29: 15.10.2024
A30: Entrega Final | B30: 5000 | C30: =B30/4 -> 1250 | F30: =2220+500+285 -> 3005
A31: Demolição | B31: 3150 | C31: =B31/4 -> 787.5
A32: 200 sacos de entulho | B32: 505 | C32: =B32/4 -> 126.25 | D32: 30.08.24
A33: Caminhão Entulho - Viagem | B33: 500 | C33: =B33/4 -> 125 | D33: 01.09.24
A34: Caminhão Entulho - Viagem | B34: 1500 | C34: =B34/4 -> 375 | D34: Projetado Setembro
A35: Materiais Elétrica | B35: 10000 | C35: =B35/4 -> 2500
A36: Material Inicial Grosso | B36: 3000 | C36: =B36/4 -> 750 | D36: Projetado Setembro
A37: Materias Hidráulica | B37: 10000 | C37: =B37/4 -> 2500
A38: Material Inicial Grosso | B38: 3000 | C38: =B38/4 -> 750 | D38: Projetado Setembro
A39: Revestimentos | B39: 22000 | C39: =B39/4 -> 5500
A40: Marcenaria | B40: 13000 | C40: =B40/4 -> 3250
A41: Sinal | B41: 5000 | C41: =B41/4 -> 1250 | D41: Projetado Setembro
...

Sheet Airbnb_csv
A1: ���Tipo | B1: C��digo de Confirma����o | C1: Data da reserva | D1: Data de in��cio | E1: Data de t��rmino | F1: Noites | G1: H��spede | H1: An��ncio | I1: Detalhes | J1: C��digo de refer��ncia | K1: Moeda | L1: Valor | M1: Pago | N1: Taxa de servi��o | O1: Taxa de pagamento r��pido | P1: Taxa de limpeza | Q1: Taxa de animais de estima����o | R1: Ganhos brutos | S1: Impostos de ocupa����o | T1: Ganhos do ano
A2: Reserva | B2: HMJ94ZXCXQ | C2: 02/26/2025 | D2: 03/07/2025 | E2: 03/09/2025 | F2: 2 | G2: Pedro Garnica | H2: Vem pro Copan, vista e design | K2: BRL | L2: 693.88 | N2: 22.12 | P2: 150.00 | Q2: 0.00 | R2: 715.36 | S2: 0.00 | T2: 2025
A3: Reserva | B3: HMK5JMXNKK | C3: 03/08/2025 | D3: 03/15/2025 | E3: 03/17/2025 | F3: 2 | G3: Andr�� Luiz Theiss | H3: Vem pro Copan, vista e design | K3: BRL | L3: 583.4 | N3: 18.60 | P3: 150.00 | Q3: 0.00 | R3: 601.46 | S3: 0.00 | T3: 2025
A4: Reserva | B4: HMZ3WB9JY4 | C4: 03/20/2025 | D4: 03/21/2025 | E4: 03/23/2025 | F4: 2 | G4: Felipe Borgognoni | H4: Vem pro Copan, vista e design | K4: BRL | L4: 505.87 | N4: 16.13 | P4: 150.00 | Q4: 0.00 | R4: 521.53 | S4: 0.00 | T4: 2025
A5: Reserva | B5: HM8YT9ENJK | C5: 03/18/2025 | D5: 03/27/2025 | E5: 03/28/2025 | F5: 1 | G5: Marcial Suarez | H5: Vem pro Copan, vista e design | K5: BRL | L5: 319.8 | N5: 10.20 | P5: 150.00 | Q5: 0.00 | R5: 329.70 | S5: 0.00 | T5: 2025
A6: Reserva | B6: HMA8X584XP | C6: 02/22/2025 | D6: 03/28/2025 | E6: 03/31/2025 | F6: 3 | G6: Matheus Arantes Cabral | H6: Vem pro Copan, vista e design | K6: BRL | L6: 703.57 | N6: 22.43 | P6: 150.00 | Q6: 0.00 | R6: 725.35 | S6: 0.00 | T6: 2025
A7: Reserva | B7: HMRH2RWZHW | C7: 04/11/2025 | D7: 04/13/2025 | E7: 04/15/2025 | F7: 2 | G7: Telma Blanco | H7: Vem pro Copan, vista e design | K7: BRL | L7: 434.63 | N7: 15.37 | P7: 150.00 | Q7: 0.00 | R7: 448.13 | S7: 0.00 | T7: 2025
A8: Reserva | B8: HMFJ83Y8AE | C8: 04/09/2025 | D8: 04/18/2025 | E8: 04/21/2025 | F8: 3 | G8: Fabio Rabelo | H8: Vem pro Copan, vista e design | K8: BRL | L8: 804.36 | N8: 25.64 | P8: 150.00 | Q8: 0.00 | R8: 829.26 | S8: 0.00 | T8: 2025
A9: Reserva | B9: HM8QH4RCKY | C9: 04/10/2025 | D9: 04/30/2025 | E9: 05/02/2025 | F9: 2 | G9: Wanessa Souza Henrique | H9: Vem pro Copan, vista e design | K9: BRL | L9: 492.58 | N9: 17.42 | P9: 150.00 | Q9: 0.00 | R9: 507.88 | S9: 0.00 | T9: 2025
A10: Reserva | B10: HMHAADATKJ | C10: 04/25/2025 | D10: 05/02/2025 | E10: 05/04/2025 | F10: 2 | G10: Tatiane Ferreira Dos Santos | H10: Vem pro Copan, vista e design | K10: BRL | L10: 585.31 | N10: 20.69 | P10: 150.00 | Q10: 0.00 | R10: 603.49 | S10: 0.00 | T10: 2025
A11: Reserva | B11: HM5ADC8D32 | C11: 04/12/2025 | D11: 05/08/2025 | E11: 05/10/2025 | F11: 2 | G11: Cristina Concone | H11: Vem pro Copan, vista e design | K11: BRL | L11: 529.29 | N11: 18.71 | P11: 150.00 | Q11: 0.00 | R11: 545.73 | S11: 0.00 | T11: 2025
A12: Reserva | B12: HM4NKXNXRS | C12: 04/22/2025 | D12: 05/10/2025 | E12: 05/15/2025 | F12: 5 | G12: Raquel Omena | H12: Vem pro Copan, vista e design | K12: BRL | L12: 1118.45 | N12: 39.55 | P12: 150.00 | Q12: 70.00 | R12: 1153.19 | S12: 0.00 | T12: 2025
A13: Reserva | B13: HMR8JXAKEC | C13: 05/06/2025 | D13: 05/15/2025 | E13: 05/16/2025 | F13: 1 | G13: Luiz Costa | H13: Vem pro Copan, vista e design | K13: BRL | L13: 318.72 | N13: 11.28 | P13: 150.00 | Q13: 0.00 | R13: 328.62 | S13: 0.00 | T13: 2025
... A31: Reserva | B31: HMZKMMTRJE | C31: 06/04/2025 | D31: 07/23/2025 | E31: 07/28/2025 | F31: 5 | G31: Rogerio Machado | H31: Vem pro Copan, vista e design | K31: BRL | L31: 1563.72 | N31: 55.28 | P31: 150.00 | Q31: 0.00 | R31: 1612.29 | S31: 0.00 | T31: 2025
A33: Tipo | B33: Código de Confirmação | C33: Data da reserva | D33: Data de início | E33: Data de término | F33: Noites | G33: Hóspede | H33: Anúncio | I33: Detalhes | J33: Código de referência | K33: Moeda | L33: Valor | M33: Pago | N33: Taxa de serviço | O33: Taxa de pagamento rápido | P33: Taxa de limpeza | Q33: Ganhos brutos | R33: Impostos de ocupação | S33: Ganhos do ano
A34: Reserva | B34: HMHTRN5835 | C34: 06/13/2025 | D34: 07/28/2025 | E34: 08/01/2025 | F34: 4 | G34: Mauro Bernardini | H34: Vem pro Copan, vista e design | K34: BRL | L34: 982.28 | N34: 34.72 | P34: 150.00 | Q34: 1012.79 | R34: 0.00 | S34: 2025
A35: Reserva | B35: HMX2E2ZMB3 | C35: 07/21/2025 | D35: 08/01/2025 | E35: 08/04/2025 | F35: 3 | G35: Henrique Tso | H35: Vem pro Copan, vista e design | K35: BRL | L35: 792.21 | N35: 37.79 | P35: 150.00 | Q35: 825.41 | R35: 0.00 | S35: 2025
A36: Reserva | B36: HMNSATNE29 | C36: 07/31/2025 | D36: 08/06/2025 | E36: 08/08/2025 | F36: 2 | G36: Leo Passos | H36: Vem pro Copan, vista e design | K36: BRL | L36: 467.68 | N36: 22.32 | P36: 150.00 | Q36: 487.28 | R36: 0.00 | S36: 2025
A37: Reserva | B37: HMA8ZXR3CW | C37: 08/03/2025 | D37: 08/08/2025 | E37: 08/12/2025 | F37: 4 | G37: Silvia Argiles Wolff | H37: Vem pro Copan, vista e design | K37: BRL | L37: 933.48 | N37: 44.52 | P37: 150.00 | Q37: 972.60 | R37: 0.00 | S37: 2025
A38: Reserva | B38: HMBKXZWFA3 | C38: 07/27/2025 | D38: 08/13/2025 | E38: 08/15/2025 | F38: 2 | G38: Rafael Sbrissia | H38: Vem pro Copan, vista e design | K38: BRL | L38: 517.31 | N38: 24.69 | P38: 150.00 | Q38: 538.99 | R38: 0.00 | S38: 2025
A39: Reserva | B39: HMYCQYMKB3 | C39: 07/15/2025 | D39: 08/15/2025 | E39: 08/17/2025 | F39: 2 | G39: Bianca Lacerda | H39: Vem pro Copan, vista e design | K39: BRL | L39: 733.08 | N39: 25.92 | P39: 150.00 | Q39: 755.85 | R39: 0.00 | S39: 2025
A40: Reserva | B40: HM32C5E4DJ | C40: 08/10/2025 | D40: 08/17/2025 | E40: 08/20/2025 | F40: 3 | G40: Olua Campos Kwiecinski | H40: Vem pro Copan, vista e design | K40: BRL | L40: 658.58 | N40: 31.42 | P40: 150.00 | Q40: 686.18 | R40: 0.00 | S40: 2025
A41: Reserva | B41: HMFZ5BHTCK | C41: 07/28/2025 | D41: 08/23/2025 | E41: 08/29/2025 | F41: 6 | G41: Annette Cotter | H41: Vem pro Copan, vista e design | K41: BRL | L41: 1388.76 | N41: 66.24 | P41: 150.00 | Q41: 1446.96 | R41: 0.00 | S41: 2025
A42: Reserva | B42: HMNKQCMDPW | C42: 08/04/2025 | D42: 08/29/2025 | E42: 08/31/2025 | F42: 2 | G42: Artur Bertone | H42: Vem pro Copan, vista e design | K42: BRL | L42: 715.85 | N42: 34.15 | P42: 150.00 | Q42: 745.85 | R42: 0.00 | S42: 2025
A45: Tipo | B45: Código de Confirmação | C45: Data da reserva | D45: Data de início | E45: Data de término | F45: Noites | G45: Hóspede | H45: Anúncio | I45: Informações | J45: Código de referência | K45: Moeda | L45: Valor | M45: Pago | N45: Taxa de serviço | O45: Taxa de pagamento rápido | P45: Taxa de limpeza | Q45: Ganhos brutos | R45: Impostos de ocupação | S45: Ganhos do ano
A47: Reserva | B47: HM9W5988ZX | C47: 08/18/2025 | D47: 09/04/2025 | E47: 09/09/2025 | F47: 5 | G47: Sandra Andrade Santos | H47: Vem pro Copan, vista e design | K47: BRL | L47: 1448.89 | N47: 69.11 | P47: 150.00 | Q47: 1509.61 | R47: 0.00 | S47: 2025
A48: Reserva | B48: HM5WFR9YF8 | C48: 08/21/2025 | D48: 09/09/2025 | E48: 09/11/2025 | F48: 2 | G48: David Neto | H48: Vem pro Copan, vista e design | K48: BRL | L48: 731.12 | N48: 34.88 | P48: 150.00 | Q48: 761.76 | R48: 0.00 | S48: 2025
A49: Reserva | B49: HMHX5WBF83 | C49: 08/16/2025 | D49: 09/11/2025 | E49: 09/19/2025 | F49: 8 | G49: George Lins | H49: Vem pro Copan, vista e design | K49: BRL | L49: 2544.61 | N49: 121.39 | P49: 150.00 | Q49: 2651.25 | R49: 0.00 | S49: 2025
A50: Reserva | B50: HMNBD2SRSW | C50: 09/01/2025 | D50: 09/19/2025 | E50: 09/22/2025 | F50: 3 | G50: Rosi Pando | H50: Vem pro Copan, vista e design | K50: BRL | L50: 811.3 | N50: 38.70 | P50: 150.00 | Q50: 845.30 | R50: 0.00 | S50: 2025
A51: Reserva | B51: HMCTFM8BFP | C51: 07/28/2025 | D51: 09/22/2025 | E51: 09/29/2025 | F51: 7 | G51: Rodrigo Junges | H51: Vem pro Copan, vista e design | K51: BRL | L51: 1460.34 | N51: 69.66 | P51: 150.00 | Q51: 1521.54 | R51: 0.00 | S51: 2025
A52: Pagamento da Resolução | B52: HMCTFM8BFP | D52: 09/22/2025 | E52: 09/29/2025 | F52: 0 | G52: Rodrigo Junges | H52: Vem pro Copan, vista e design | I52: Pagamento para a resolução CLA-YBF9YB2BDT da reserva HMCTFM8BFP | K52: BRL | L52: 114 | Q52: 114.00 | S52: 2025
A55: Tipo | B55: Código de Confirmação | C55: Data da reserva | D55: Data de início | E55: Data de término | F55: Noites | G55: Hóspede | H55: Anúncio | I55: Informações | J55: Código de referência | K55: Moeda | L55: Valor | M55: Pago | N55: Taxa de serviço | O55: Taxa de pagamento rápido | P55: Taxa de limpeza | Q55: Ganhos brutos | R55: Impostos de ocupação | S55: Ganhos do ano
A56: Reserva | B56: HMFHY2M4AN | C56: 09/14/2025 | D56: 10/01/2025 | E56: 10/06/2025 | F56: 5 | G56: Iuri Santos | H56: Vem pro Copan, vista e design | K56: BRL | L56: 1296.17 | N56: 61.83 | P56: 150.00 | Q56: 1350.49 | R56: 0.00 | S56: 2025
A57: Pagamento da Resolução | B57: HMFHY2M4AN | D57: 10/01/2025 | E57: 10/06/2025 | F57: 5 | G57: Iuri Santos | H57: Vem pro Copan, vista e design | I57: Pagamento para a resolução CLA-93NBTKTBYT da reserva HMFHY2M4AN | K57: BRL | L57: 160 | Q57: 160.00 | S57: 2025
A58: Reserva | B58: HM8ER5HS5B | C58: 10/05/2025 | D58: 10/07/2025 | E58: 10/09/2025 | F58: 2 | G58: Thalia Vieira | H58: Vem pro Copan, vista e design | K58: BRL | L58: 448.6 | N58: 21.40 | P58: 150.00 | Q58: 467.40 | R58: 0.00 | S58: 2025
A59: Reserva | B59: HME8PKD2SN | C59: 09/08/2025 | D59: 10/09/2025 | E59: 10/13/2025 | F59: 4 | G59: Eber Marzulo | H59: Vem pro Copan, vista e design | K59: BRL | L59: 1212.18 | N59: 57.82 | P59: 150.00 | Q59: 1262.98 | R59: 0.00 | S59: 2025
A60: Reserva | B60: HM25D5B8EB | C60: 10/03/2025 | D60: 10/15/2025 | E60: 10/17/2025 | F60: 2 | G60: Frederico Coelho | H60: Vem pro Copan, vista e design | K60: BRL | L60: 559.32 | N60: 26.68 | P60: 150.00 | Q60: 582.76 | R60: 0.00 | S60: 2025
A61: Reserva | B61: HM3J3CS4WB | C61: 10/07/2025 | D61: 10/17/2025 | E61: 10/19/2025 | F61: 2 | G61: Anna Clara De Faria Lima | H61: Vem pro Copan, vista e design | K61: BRL | L61: 715.85 | N61: 34.15 | P61: 150.00 | Q61: 745.85 | R61: 0.00 | S61: 2025
A62: Reserva | B62: HMHHQ3BMMP | C62: 09/07/2025 | D62: 10/23/2025 | E62: 10/27/2025 | F62: 4 | G62: Juliana Cristina | H62: Vem pro Copan, vista e design | K62: BRL | L62: 1212.18 | N62: 57.82 | P62: 150.00 | Q62: 1262.98 | R62: 0.00 | S62: 2025
A63: Reserva | B63: HMCN2TBS4C | C63: 10/01/2025 | D63: 10/29/2025 | E63: 11/02/2025 | F63: 4 | G63: Paloma Martins | H63: Vem pro Copan, vista e design | K63: BRL | L63: 1078.55 | N63: 51.45 | P63: 150.00 | Q63: 1123.75 | R63: 0.00 | S63: 2025
...

Sheet Booking
A1: Book Number | B1: Booked by | C1: Guest Name(s) | D1: Check-in | E1: Check-out | F1: Booked on | G1: Status | H1: Rooms | I1: People | J1: Adults | K1: Children | L1: Children's age(s) | M1: Price | N1: Commission % | O1: Commission Amount | P1: Payment Status | Q1: Payment method (payment provider) | R1: Remarks | S1: Booker group | T1: Booker country | U1: Travel purpose | V1: Device | W1: Unit type | X1: Duration (nights) | Y1: Cancellation date | Z1: Address | AA1: Phone number
A2: 4295492340 | B2: Luana, Paulino | C2: Paulino Luana | D2: 2025-04-05 | E2: 2025-04-09 | F2: 2025-02-17 21:46:10 | G2: ok | H2: 1 | I2: 2 | M2: 1270 | N2: 14 | O2: 177.8 | P2: Paid online | T2: br | U2: Leisure | V2: Mobile | W2: One-Bedroom Apartment | X2: 4
A3: 4319155308 | B3: Fabio, Jeane | C3: Jeane Fabio | D3: 2025-04-09 | E3: 2025-04-13 | F3: 2025-03-28 08:52:13 | G3: ok | H3: 1 | I3: 2 | M3: 950 | N3: 14 | O3: 133 | P3: Paid online | T3: br | U3: Business | V3: Mobile | W3: One-Bedroom Apartment | X3: 4 | Z3: Rua Riachuelo 545
A4: 4470959558 | B4: Sapelli, Dani | C4: Dani Sapelli | D4: 2025-04-13 | E4: 2025-04-16 | F4: 2025-04-07 15:41:10 | G4: cancelled_by_guest | H4: 1 | I4: 2 | M4: 600 | N4: 14 | T4: br | U4: Business | V4: Mobile | W4: One-Bedroom Apartment | X4: 3 | Y4: 2025-04-08 15:17:09 | Z4: rua bom jesus de iguape, 5415
A5: 4680103360 | B5: Vitorino, Felipe | C5: Felipe Vitorino | D5: 2025-04-27 | E5: 2025-04-29 | F5: 2025-04-24 15:58:07 | G5: cancelled_by_guest | H5: 1 | I5: 2 | M5: 540 | N5: 14 | T5: br | U5: Leisure | V5: Mobile | W5: One-Bedroom Apartment | X5: 2 | Y5: 2025-04-24 23:39:16 | Z5: Rua Republica do Peru, 327
A7: Reservation number | B7: Invoice number | C7: Booked on | D7: Arrival | E7: Departure | F7: Booker name | G7: Guest name | H7: Rooms | I7: Persons | J7: Room nights | K7: Commission % | L7: Original amount | M7: Final amount | N7: Commission amount | O7: Status | P7: Guest request | Q7: Currency | R7: Hotel id | S7: Property name | T7: City | U7: Country
A8: 4330982423 | B8: 19924068 | C8: 2025-05-16T03:30:50 | D8: 2025-05-25 | E8: 2025-05-30 | F8: Alcimar Olavo | G8: Alcimar Olavo | H8: 1 | I8: 2 | J8: 5 | K8: 13.00 | L8: 850 | M8: 850 | N8: 110.5 | O8: OK | Q8: BRL | R8: 13603631 | S8: Copan Incrível, totalmente novo, andar alto, vista e pôr-do-sol, design, arquitetura, home office, Smart TV 70", Wi-Fi e ar condicionado | T8: São Paulo | U8: Brazil
A10: Book Number | B10: Booked by | C10: Guest Name(s) | D10: Check-in | E10: Check-out | F10: Booked on | G10: Status | H10: Rooms | I10: People | J10: Adults | K10: Children | L10: Children's age(s) | M10: Price | N10: Commission % | O10: Commission Amount | P10: Payment Status | Q10: Payment method (payment provider) | R10: Remarks | S10: Booker group | T10: Booker country | U10: Travel purpose | V10: Device | W10: Unit type | X10: Duration (nights) | Y10: Cancellation date | Z10: Address | AA10: Phone number
A11: 4827819677 | B11: Antunes Silva, Abraao | C11: Abraao Antunes Silva | D11: 2025-06-08 | E11: 2025-06-09 | F11: 2025-05-14 22:05:19 | G11: ok | H11: 1 | I11: 2 | M11: 330 BRL | N11: 13 | O11: 42.9 BRL | P11: Paid online | T11: br | U11: Leisure | V11: Mobile | W11: One-Bedroom Apartment | X11: 1 | Z11: Rua Irene Naresi De Morais
A12: 4427617314 | B12: Cabral, Joyce | C12: Joyce Cabral | D12: 2025-06-11 | E12: 2025-06-13 | F12: 2025-05-24 20:32:45 | G12: ok | H12: 1 | I12: 2 | M12: 510 BRL | N12: 13 | O12: 66.3 BRL | P12: Paid online | T12: br | U12: Leisure | V12: Mobile | W12: One-Bedroom Apartment | X12: 2 | Z12: Rua Adherbal Stresser
A14: Book Number | B14: Booked by | C14: Guest Name(s) | D14: Check-in | E14: Check-out | F14: Booked on | G14: Status | H14: Rooms | I14: People | J14: Adults | K14: Children | L14: Children's age(s) | M14: Price | N14: Commission % | O14: Commission Amount | P14: Payment Status | Q14: Payment method (payment provider) | R14: Remarks | S14: Booker group | T14: Booker country | U14: Travel purpose | V14: Device | W14: Unit type | X14: Duration (nights) | Y14: Cancellation date | Z14: Address | AA14: Phone number
A15: 5827715021 | B15: Winkler, Beat | C15: Beat Winkler | D15: 2025-08-21 | E15: 2025-08-23 | F15: 2025-08-10 10:25:10 | G15: ok | H15: 1 | I15: 2 | M15: 630 BRL | N15: 13 | O15: 81.9 BRL | P15: Paid online | T15: br | U15: Leisure | V15: Desktop | W15: One-Bedroom Apartment | X15: 2 | Z15: rua professor miguel msuricio da rocha 840b
